<?xml version="1.0" ?>
<sdf version="1.9">
  <model name="custom_rover">
    <static>false</static>
    <self_collide>false</self_collide>
    
    <!-- Chassis Link -->
    <link name="chassis">
      <pose>0 0 0.3 0 0 0</pose>
      
      <inertial>
        <mass>50.0</mass>
        <inertia>
          <ixx>2.0</ixx>
          <ixy>0</ixy>
          <ixz>0</ixz>
          <iyy>3.0</iyy>
          <iyz>0</iyz>
          <izz>4.0</izz>
        </inertia>
      </inertial>
      
      <collision name="collision">
        <geometry>
          <box>
            <size>1.2 0.8 0.3</size>
          </box>
        </geometry>
      </collision>
      
      <visual name="visual">
        <geometry>
          <box>
            <size>1.2 0.8 0.3</size>
          </box>
        </geometry>
        <material>
          <ambient>0.3 0.3 0.3 1</ambient>
          <diffuse>0.4 0.4 0.4 1</diffuse>
          <specular>0.5 0.5 0.5 1</specular>
        </material>
      </visual>
    </link>
    
    <!-- Front Left Wheel -->
    <link name="front_left_wheel">
      <pose>0.4 0.5 0.15 -1.5707 0 0</pose>
      <inertial>
        <mass>5.0</mass>
        <inertia>
          <ixx>0.05</ixx>
          <ixy>0</ixy>
          <ixz>0</ixz>
          <iyy>0.05</iyy>
          <iyz>0</iyz>
          <izz>0.05</izz>
        </inertia>
      </inertial>
      <collision name="collision">
        <geometry>
          <cylinder>
            <radius>0.15</radius>
            <length>0.15</length>
          </cylinder>
        </geometry>
        <surface>
          <friction>
            <ode>
              <mu>1.0</mu>
              <mu2>1.0</mu2>
            </ode>
          </friction>
        </surface>
      </collision>
      <visual name="visual">
        <geometry>
          <cylinder>
            <radius>0.15</radius>
            <length>0.15</length>
          </cylinder>
        </geometry>
        <material>
          <ambient>0.1 0.1 0.1 1</ambient>
          <diffuse>0.2 0.2 0.2 1</diffuse>
          <specular>0.1 0.1 0.1 1</specular>
        </material>
      </visual>
    </link>
    
    <!-- Front Right Wheel -->
    <link name="front_right_wheel">
      <pose>0.4 -0.5 0.15 -1.5707 0 0</pose>
      <inertial>
        <mass>5.0</mass>
        <inertia>
          <ixx>0.05</ixx>
          <ixy>0</ixy>
          <ixz>0</ixz>
          <iyy>0.05</iyy>
          <iyz>0</iyz>
          <izz>0.05</izz>
        </inertia>
      </inertial>
      <collision name="collision">
        <geometry>
          <cylinder>
            <radius>0.15</radius>
            <length>0.15</length>
          </cylinder>
        </geometry>
        <surface>
          <friction>
            <ode>
              <mu>1.0</mu>
              <mu2>1.0</mu2>
            </ode>
          </friction>
        </surface>
      </collision>
      <visual name="visual">
        <geometry>
          <cylinder>
            <radius>0.15</radius>
            <length>0.15</length>
          </cylinder>
        </geometry>
        <material>
          <ambient>0.1 0.1 0.1 1</ambient>
          <diffuse>0.2 0.2 0.2 1</diffuse>
          <specular>0.1 0.1 0.1 1</specular>
        </material>
      </visual>
    </link>
    
    <!-- Rear Left Wheel -->
    <link name="rear_left_wheel">
      <pose>-0.4 0.5 0.15 -1.5707 0 0</pose>
      <inertial>
        <mass>5.0</mass>
        <inertia>
          <ixx>0.05</ixx>
          <ixy>0</ixy>
          <ixz>0</ixz>
          <iyy>0.05</iyy>
          <iyz>0</iyz>
          <izz>0.05</izz>
        </inertia>
      </inertial>
      <collision name="collision">
        <geometry>
          <cylinder>
            <radius>0.15</radius>
            <length>0.15</length>
          </cylinder>
        </geometry>
        <surface>
          <friction>
            <ode>
              <mu>1.0</mu>
              <mu2>1.0</mu2>
            </ode>
          </friction>
        </surface>
      </collision>
      <visual name="visual">
        <geometry>
          <cylinder>
            <radius>0.15</radius>
            <length>0.15</length>
          </cylinder>
        </geometry>
        <material>
          <ambient>0.1 0.1 0.1 1</ambient>
          <diffuse>0.2 0.2 0.2 1</diffuse>
          <specular>0.1 0.1 0.1 1</specular>
        </material>
      </visual>
    </link>
    
    <!-- Rear Right Wheel -->
    <link name="rear_right_wheel">
      <pose>-0.4 -0.5 0.15 -1.5707 0 0</pose>
      <inertial>
        <mass>5.0</mass>
        <inertia>
          <ixx>0.05</ixx>
          <ixy>0</ixy>
          <ixz>0</ixz>
          <iyy>0.05</iyy>
          <iyz>0</iyz>
          <izz>0.05</izz>
        </inertia>
      </inertial>
      <collision name="collision">
        <geometry>
          <cylinder>
            <radius>0.15</radius>
            <length>0.15</length>
          </cylinder>
        </geometry>
        <surface>
          <friction>
            <ode>
              <mu>1.0</mu>
              <mu2>1.0</mu2>
            </ode>
          </friction>
        </surface>
      </collision>
      <visual name="visual">
        <geometry>
          <cylinder>
            <radius>0.15</radius>
            <length>0.15</length>
          </cylinder>
        </geometry>
        <material>
          <ambient>0.1 0.1 0.1 1</ambient>
          <diffuse>0.2 0.2 0.2 1</diffuse>
          <specular>0.1 0.1 0.1 1</specular>
        </material>
      </visual>
    </link>
    
    <!-- Lidar Link -->
    <link name="lidar_link">
      <pose>0 0 0.65 0 0 0</pose>
      <inertial>
        <mass>0.5</mass>
        <inertia>
          <ixx>0.001</ixx>
          <ixy>0</ixy>
          <ixz>0</ixz>
          <iyy>0.001</iyy>
          <iyz>0</iyz>
          <izz>0.001</izz>
        </inertia>
      </inertial>
      <collision name="collision">
        <geometry>
          <cylinder>
            <radius>0.08</radius>
            <length>0.1</length>
          </cylinder>
        </geometry>
      </collision>
      <visual name="visual">
        <geometry>
          <cylinder>
            <radius>0.08</radius>
            <length>0.1</length>
          </cylinder>
        </geometry>
        <material>
          <ambient>0 0 1 1</ambient>
          <diffuse>0 0.5 1 1</diffuse>
          <specular>0.8 0.8 0.8 1</specular>
        </material>
      </visual>
      
      <!-- Lidar Sensor -->
      <sensor name="lidar_sensor" type="ray">
        <pose>0 0 0.05 0 0 0</pose>
        <topic>lidar</topic>
        <update_rate>10</update_rate>
        <visualize>false</visualize>
        <always_on>true</always_on>
        <ray>
          <scan>
            <horizontal>
              <samples>640</samples>
              <resolution>1</resolution>
              <min_angle>-2.356</min_angle>
              <max_angle>2.356</max_angle>
            </horizontal>
          </scan>
          <range>
            <min>0.1</min>
            <max>30.0</max>
            <resolution>0.01</resolution>
          </range>
        </ray>
      </sensor>
    </link>
    
    <!-- Wheel Joints -->
    <joint name="front_left_wheel_joint" type="revolute">
      <parent>chassis</parent>
      <child>front_left_wheel</child>
      <axis>
        <xyz>0 0 1</xyz>
        <limit>
          <lower>-1e16</lower>
          <upper>1e16</upper>
        </limit>
      </axis>
    </joint>
    
    <joint name="front_right_wheel_joint" type="revolute">
      <parent>chassis</parent>
      <child>front_right_wheel</child>
      <axis>
        <xyz>0 0 1</xyz>
        <limit>
          <lower>-1e16</lower>
          <upper>1e16</upper>
        </limit>
      </axis>
    </joint>
    
    <joint name="rear_left_wheel_joint" type="revolute">
      <parent>chassis</parent>
      <child>rear_left_wheel</child>
      <axis>
        <xyz>0 0 1</xyz>
        <limit>
          <lower>-1e16</lower>
          <upper>1e16</upper>
        </limit>
      </axis>
    </joint>
    
    <joint name="rear_right_wheel_joint" type="revolute">
      <parent>chassis</parent>
      <child>rear_right_wheel</child>
      <axis>
        <xyz>0 0 1</xyz>
        <limit>
          <lower>-1e16</lower>
          <upper>1e16</upper>
        </limit>
      </axis>
    </joint>
    
    <joint name="lidar_joint" type="fixed">
      <parent>chassis</parent>
      <child>lidar_link</child>
    </joint>
    
    <!-- Differential Drive Plugin -->
    <plugin
      filename="ignition-gazebo-diff-drive-system"
      name="ignition::gazebo::systems::DiffDrive">
      <left_joint>front_left_wheel_joint</left_joint>
      <left_joint>rear_left_wheel_joint</left_joint>
      <right_joint>front_right_wheel_joint</right_joint>
      <right_joint>rear_right_wheel_joint</right_joint>
      <wheel_separation>1.0</wheel_separation>
      <wheel_radius>0.15</wheel_radius>
      <odom_publish_frequency>50</odom_publish_frequency>
      <topic>cmd_vel</topic>
      <odom_topic>odom</odom_topic>
      <tf_topic>tf</tf_topic>
      <frame_id>odom</frame_id>
      <child_frame_id>chassis</child_frame_id>
    </plugin>
    
  </model>
</sdf>
